<mujoco model="table_cabinet_arena">
  <asset>
    <texture builtin="gradient" height="256" rgb1=".9 .9 1." rgb2=".2 .3 .4" type="skybox" width="256"/>
    <texture builtin="checker" height="512" name="texplane" rgb1=".2 .3 .4" rgb2=".1 0.15 0.2" type="2d" width="512"/>
    <material name="floorplane" reflectance="0.5" texrepeat="1 1" texture="texplane" texuniform="true"/>
    <mesh name="cabinet_body" file="./cabinet/cabinet_body.STL" scale="0.001 0.001 0.001" />
    <mesh name="cabinet_door" file="./cabinet/cabinet_door.STL" scale="0.001 0.001 0.001" />
    <mesh name="cabinet_knob" file="./cabinet/cabinet_knob.STL" scale="0.001 0.001 0.001" />
  </asset>
  <worldbody>
    <geom condim="3" material="floorplane" name="floor" pos="0 0 0" size="3 3 .125" type="plane"/>
    <body name="table" pos="0 0 0.4">
      <geom pos="0 0 0" size="0.4 0.4 0.4" type="box" name="table_collision" friction="1 0.005 0.0001"/>
      <geom pos="0 0 0" size="0.4 0.4 0.4" type="box" conaffinity="0" contype="0" group="1" name="table_visual"/>
      <site pos="0 0 0.4" name="table_top" size="0.001 0.001 0.001" rgba="0 0 0 0"/>
    </body>

    <light diffuse=".8 .8 .8" dir="0 -.15 -1" directional="false" pos="1 1 4.0" specular="0.3 0.3 0.3" castshadow="false"/>
    <light diffuse=".8 .8 .8" dir="0 -.15 -1" directional="false" pos="-3. -3. 4.0" specular="0.3 0.3 0.3" castshadow="false"/>
    <!-- front view -->
    <camera mode="fixed" name="frontview" pos="1.6 0 1.45" quat="0.56 0.43 0.43 0.56"/>
    <!-- bird view -->
    <camera mode="fixed" name="birdview" pos="-0.2 0 3.0" quat="0.7071 0 0 0.7071"/>
    <!-- agent view -->
    <camera mode="fixed" name="agentview" pos="0.5 0 1.35" quat="0.653 0.271 0.271 0.653"/>

    <geom quat="0.5 0.5 0.5 0.5" pos="0 -0.4 0.8"  type="mesh" contype="0" conaffinity="0" group="1" rgba="0 0 0.8 1" mesh="cabinet_body" />

    <body name="door_link" pos="0.0 0.38 0.895" quat="0.707 0 0 0.707" >
        <inertial pos="-0.0322282 0.000814966 0.0321541" quat="0.706133 -0.0631938 -0.0614386 0.702573" mass="1.343" diaginertia="0.115549 0.0813332 0.0350412" />
        <joint name="base_to_door" pos="0 0 0" axis="0 0 1" limited="true" range="0 1.0" />
        <geom pos="0.006 -0.0055 0" quat="0.000563312 0.000562864 0.706825 0.707388" type="mesh" contype="0" conaffinity="0" group="1" rgba="1 1 1 1" mesh="cabinet_door" />
        <geom pos="-0.2175 0.0055 0.217" type="mesh" contype="0" conaffinity="0" group="1" rgba="0 0 0 1" mesh="cabinet_knob" />
    </body>
  </worldbody>
</mujoco>